self.bias is not updating unless the program is reset
this:
    urllib3.exceptions.ProtocolError: ('Connection aborted.', TimeoutError(10060, 'A connection attempt failed because the connected party did not properly respond after a period of time, or established connection failed because connected host has failed to respond', None, 10060, None))

    During handling of the above exception, another exception occurred:

    Traceback (most recent call last):
      File "C:/learnincode/Trading bot/Scan.py", line 131, in <module>
        scan.start()
      File "C:/learnincode/Trading bot/Scan.py", line 125, in start
        self.lookForTrades()
      File "C:/learnincode/Trading bot/Scan.py", line 41, in lookForTrades
        self.onTick()
      File "C:/learnincode/Trading bot/Scan.py", line 74, in onTick
        self.lastXClosingPrices = self.getClosingPrices(10)
      File "C:/learnincode/Trading bot/Scan.py", line 113, in getClosingPrices
        candles = Scan.alpacaAPI.get_barset(symbols=self.symbol, limit=amount, end="{}-04:00".format(
      File "C:\learnincode\Trading bot\venv\lib\site-packages\alpaca_trade_api\rest.py", line 359, in get_barset
        resp = self.data_get('/bars/{}'.format(timeframe), params)
      File "C:\learnincode\Trading bot\venv\lib\site-packages\alpaca_trade_api\rest.py", line 165, in data_get
        return self._request(
      File "C:\learnincode\Trading bot\venv\lib\site-packages\alpaca_trade_api\rest.py", line 115, in _request
        return self._one_request(method, url, opts, retry)
      File "C:\learnincode\Trading bot\venv\lib\site-packages\alpaca_trade_api\rest.py", line 134, in _one_request
        resp = self._session.request(method, url, **opts)
      File "C:\learnincode\Trading bot\venv\lib\site-packages\requests\sessions.py", line 530, in request
        resp = self.send(prep, **send_kwargs)
      File "C:\learnincode\Trading bot\venv\lib\site-packages\requests\sessions.py", line 643, in send
        r = adapter.send(request, **kwargs)
      File "C:\learnincode\Trading bot\venv\lib\site-packages\requests\adapters.py", line 498, in send
        raise ConnectionError(err, request=request)
    requests.exceptions.ConnectionError: ('Connection aborted.', TimeoutError(10060, 'A connection attempt failed because the connected party did not properly respond after a period of time, or established connection failed because connected host has failed to respond', None, 10060, None))

    might have been my laptop disconnecting